Workbook

Sheet Dashboard
A1: India Startup Funding Tracker
A2: Rounds announced 02 Jan 2025 to 10 Oct 2026, cross-checked across Entrackr, Inc42, The Economic Times, VCCircle. Built 11 Oct 2026.
A4: Rounds tracked | D4: Disclosed funding, USD bn | G4: Median round, USD mn | J4: Source reports matched | M4: Duplicate reports merged | P4: Amount disagreements over 10%
A5: =COUNTA(Rounds!$A$2:$A$2179) -> 2178 | D5: =SUM(Rounds!$E$2:$E$2179)/1000 -> 28.468859 | G5: =MEDIAN(Rounds!$E$2:$E$2179) -> 3.5 | J5: =COUNTA(Reports!$A$5:$A$4463) -> 4459 | M5: =J5-A5 -> 2281 | P5: =COUNTIF(Rounds!$P$2:$P$2179,">10") -> 68
A6: 70% confirmed by 2+ sources | D6: 2,013 rounds disclosed an amount | G6: half of disclosed rounds are smaller | J6: articles, table rows and headlines | M6: 228 needed name matching | P6: rounds where sources differ
A23: The last month shown is partial: data runs to 10 Oct 2026.
A46: Look up a round
A47: Round ID | C47: R261010-nathabit | F47: pick an ID from the list, or paste one from the Rounds sheet
A48: Company | C48: =IFERROR(IF(INDEX(Rounds!$B$2:$B$2179,MATCH($C$47,Rounds!$A$2:$A$2179,0))="","",INDEX(Rounds!$B$2:$B$2179,MATCH($C$47,Rounds!$A$2:$A$2179,0))),"not found") -> Nat Habit
A49: Announced | C49: =IFERROR(IF(INDEX(Rounds!$C$2:$C$2179,MATCH($C$47,Rounds!$A$2:$A$2179,0))="","",INDEX(Rounds!$C$2:$C$2179,MATCH($C$47,Rounds!$A$2:$A$2179,0))),"not found") -> 46305
A50: Amount (USD mn) | C50: =IFERROR(IF(INDEX(Rounds!$E$2:$E$2179,MATCH($C$47,Rounds!$A$2:$A$2179,0))="","",INDEX(Rounds!$E$2:$E$2179,MATCH($C$47,Rounds!$A$2:$A$2179,0))),"not found") -> 14.68
A51: As reported | C51: =IFERROR(IF(INDEX(Rounds!$G$2:$G$2179,MATCH($C$47,Rounds!$A$2:$A$2179,0))="","",INDEX(Rounds!$G$2:$G$2179,MATCH($C$47,Rounds!$A$2:$A$2179,0))),"not found") -> Rs 142 crore
A52: Stage | C52: =IFERROR(IF(INDEX(Rounds!$H$2:$H$2179,MATCH($C$47,Rounds!$A$2:$A$2179,0))="","",INDEX(Rounds!$H$2:$H$2179,MATCH($C$47,Rounds!$A$2:$A$2179,0))),"not found") -> Undisclosed
A53: Sector | C53: =IFERROR(IF(INDEX(Rounds!$J$2:$J$2179,MATCH($C$47,Rounds!$A$2:$A$2179,0))="","",INDEX(Rounds!$J$2:$J$2179,MATCH($C$47,Rounds!$A$2:$A$2179,0))),"not found") -> Ecommerce
A54: City | C54: =IFERROR(IF(INDEX(Rounds!$K$2:$K$2179,MATCH($C$47,Rounds!$A$2:$A$2179,0))="","",INDEX(Rounds!$K$2:$K$2179,MATCH($C$47,Rounds!$A$2:$A$2179,0))),"not found") -> Unknown
A55: Lead investors | C55: =IFERROR(IF(INDEX(Rounds!$L$2:$L$2179,MATCH($C$47,Rounds!$A$2:$A$2179,0))="","",INDEX(Rounds!$L$2:$L$2179,MATCH($C$47,Rounds!$A$2:$A$2179,0))),"not found") -> Trident Growth Partners
A56: Sources | C56: =IFERROR(IF(INDEX(Rounds!$N$2:$N$2179,MATCH($C$47,Rounds!$A$2:$A$2179,0))="","",INDEX(Rounds!$N$2:$N$2179,MATCH($C$47,Rounds!$A$2:$A$2179,0))),"not found") -> et
A57: Flags | C57: =IFERROR(IF(INDEX(Rounds!$Q$2:$Q$2179,MATCH($C$47,Rounds!$A$2:$A$2179,0))="","",INDEX(Rounds!$Q$2:$Q$2179,MATCH($C$47,Rounds!$A$2:$A$2179,0))),"not found") -> C04 C07
A59: Flags are check IDs from the Checks sheet. PivotTables are on the By Sector, By Stage and By City sheets and refresh when the file opens.

Sheet Rounds
A1: Round ID | B1: Company | C1: Announced | D1: Month | E1: Amount (USD mn) | F1: Amount (INR cr) | G1: As reported | H1: Stage | I1: Stage group | J1: Sector | K1: City | L1: Lead investors | M1: Investors | N1: Sources | O1: Source count | P1: Amount spread % | Q1: Flags | R1: First source link
A2: R250102-ayefinance | B2: Aye Finance | C2: 45659 | D2: 45658 | E2: 12.8 | F2: 109.77 | G2: $12.8 Mn | H2: Debt | I2: Debt | J2: Fintech | K2: Unknown | M2: Northern Arc; ASK Financial Holdings; MAS Financial Services; CredAvenue | N2: inc42 | O2: 1 | P2: 0 | Q2: C07 | R2: https://inc42.com/buzz/from-aye-finance-to-klassroom-indian-startups-raised-14-mn-this-week/
A3: R250102-cargofl | B3: CargoFL | C3: 45659 | D3: 45658 | E3: 0.787 | F3: 6.75 | G3: Rs 6.75 crore | H3: Seed | I3: Early | J3: Logistics | K3: Pune | L3: YourNest Venture Capital | M3: YourNest Venture Capital; Real Time Angel Fund; Peaceful Progress Angel Fund; Sanchi Connect Accelerator; Dinesh Chandra Agarwal; Dinesh Gulati; Murugavel Janakiraman; Rajesh Sawhney | N3: entrackr | inc42 | O3: 2 | P3: 0 | R3: https://entrackr.com/snippets/cargofl-raises-seed-funding-round-8584928
A4: R250102-klassroom | B4: Klassroom | C4: 45659 | D4: 45658 | H4: Pre-Series A | I4: Early | J4: Edtech | K4: Unknown | M4: LetsVenture; Hem Securities; Meteor Ventures; Growth Sense Fund | N4: inc42 | O4: 1 | Q4: C03 C07 | R4: https://inc42.com/buzz/from-aye-finance-to-klassroom-indian-startups-raised-14-mn-this-week/
A5: R250104-oyo | B5: OYO | C5: 45661 | D5: 45658 | E5: 64.125 | F5: 550 | G5: Rs 550 crore | H5: Undisclosed | I5: Undisclosed | J5: Travel Tech | K5: Delhi NCR | L5: Redsprig Innovation Partners | M5: Redsprig Innovation Partners; Ritesh Agarwal | N5: entrackr | inc42 | O5: 2 | P5: 1.4 | Q5: C04 | R5: https://entrackr.com/news/oyo-raises-65-mn-from-ritesh-agarwals-redsprig-innovation-8591029
A6: R250106-blackcarrot | B6: BlackCarrot | C6: 45663 | D6: 45658 | H6: Seed | I6: Early | J6: Ecommerce | K6: Unknown | L6: Circle | M6: Circle; EvolveX accelerator; Suraj Nalin | N6: inc42 | O6: 1 | Q6: C03 C07 | R6: https://inc42.com/buzz/from-innovaccer-to-beyond-snack-indian-startups-raised-432-mn-this-week/
A7: R250106-consintai | B7: Consint.AI | C7: 45663 | D7: 45658 | E7: 0.584 | F7: 5 | G7: Rs 5 crore | H7: Seed | I7: Early | J7: Artificial Intelligence | K7: Delhi NCR | L7: Equanimity Ventures; Seafund | M7: Equanimity Ventures; Seafund | N7: entrackr | et | O7: 2 | P7: 0 | R7: https://entrackr.com/snippets/genai-startup-consintai-raises-rs-5-cr-in-seed-round-8594981
A8: R250106-spintly | B8: Spintly | C8: 45663 | D8: 45658 | E8: 0.409 | F8: 3.5 | G8: Rs 3.5 crore | H8: Seed | I8: Early | J8: Deeptech | K8: Goa | L8: Spyre VC; Chakra Growth Fund; Alumni Ventures; Doctor Technology | M8: Spyre VC; Chakra Growth Fund; Alumni Ventures; Doctor Technology; Accel India | N8: entrackr | inc42 | O8: 2 | P8: 0.4 | R8: https://entrackr.com/snippets/proptech-startup-spintly-raises-rs-35-cr-in-extended-seed-round-8594970
A9: R250107-bodmastechnolo | B9: Bodmas Technologies | C9: 45664 | D9: 45658 | H9: Undisclosed | I9: Undisclosed | J9: Enterprise Tech | K9: Unknown | M9: Auxano Capital | N9: inc42 | O9: 1 | Q9: C03 C04 C07 | R9: https://inc42.com/buzz/from-innovaccer-to-beyond-snack-indian-startups-raised-432-mn-this-week/
A10: R250107-emoenergy | B10: EMO Energy | C10: 45664 | D10: 45658 | E10: 6.2 | F10: 53.16 | G10: $6.2 million | H10: Series A | I10: Early | J10: Cleantech | K10: Bengaluru | L10: Subhkam Ventures; Transition VC | M10: Subhkam Ventures; Transition VC; Microtek Group; SRK Family Office | N10: entrackr | inc42 | et | O10: 3 | P10: 0 | R10: https://entrackr.com/snippets/emo-energy-raises-62-mn-in-series-a-round-8598190
A11: R250107-kibisports | B11: KIBI Sports | C11: 45664 | D11: 45658 | E11: 0.1 | F11: 0.86 | G11: $100,000 | H11: Pre-Seed | I11: Early | J11: Media & Entertainment | K11: Bengaluru | M11: Saurabh Aggarwal; Arpit Bhardwaj; Vartika Joshi; Suryansh Jain; Pranjal Bansal; Amit Kumar Sahu; Pratibha Rani; Sushila | N11: entrackr | O11: 1 | P11: 0 | R11: https://entrackr.com/snippets/kibi-sports-raises-100k-in-pre-seed-funding-8598246
A12: R250107-moonrider | B12: Moonrider | C12: 45664 | D12: 45658 | E12: 2.2 | F12: 18.86 | G12: $2.2 million | H12: Seed | I12: Early | J12: Cleantech | K12: Bengaluru | L12: Micelio Fund | M12: Micelio Fund | N12: entrackr | inc42 | et | O12: 3 | P12: 0 | R12: https://entrackr.com/snippets/electric-tractor-startup-moonrider-raises-22-mn-in-seed-round-8597800
A13: R250107-obenelectric | B13: Oben Electric | C13: 45664 | D13: 45658 | E13: 5.832 | F13: 50 | G13: Rs 50 crore | H13: Series A | I13: Early | J13: Cleantech | K13: Bengaluru | M13: Ambis Holding US; Kuberans Ventures; Karimjee Group; Mission Vertical Capital; Sanjeev Saraf | N13: entrackr | inc42 | O13: 2 | P13: 0.5 | R13: https://entrackr.com/snippets/oben-electric-raises-6-mn-in-series-a-8598547
A14: R250107-pratilipi | B14: Pratilipi | C14: 45664 | D14: 45658 | E14: 1.2 | F14: 10.29 | G14: $1.2 Mn | H14: Undisclosed | I14: Undisclosed | J14: Media & Entertainment | K14: Delhi NCR | L14: Alteria Capital | M14: Alteria Capital | N14: inc42 | O14: 1 | P14: 0 | Q14: C04 | R14: https://inc42.com/buzz/from-innovaccer-to-beyond-snack-indian-startups-raised-432-mn-this-week/
A15: R250107-vehanttechnolo | B15: Vehant Technologies | C15: 45664 | D15: 45658 | E15: 9 | F15: 77.17 | G15: $9 million | H15: Debt | I15: Debt | J15: Unclassified | K15: Delhi NCR | M15: True North | N15: entrackr | et | O15: 2 | P15: 0 | Q15: C06 | R15: https://economictimes.indiatimes.com/tech/funding/vehant-technologies-raises-9-million-from-true-north-through-ncds-plans-ipo-by-2026/articleshow/117013023.cms
A16: R250107-zoplar | B16: Zoplar | C16: 45664 | D16: 45658 | E16: 3.4 | F16: 29.15 | G16: $3.4 million | H16: Series A | I16: Early | J16: Healthtech | K16: Delhi NCR | L16: Blume Ventures | M16: Blume Ventures; BEENEXT; Saison Capital; Finfirst; LogX Ventures | N16: entrackr | inc42 | O16: 2 | P16: 0 | R16: https://entrackr.com/snippets/blume-ventures-leads-34-mn-round-in-zoplar-8598758
A17: R250108-brainsightai | B17: BrainSinghtAI | C17: 45665 | D17: 45658 | E17: 5 | F17: 42.94 | G17: $5 million | H17: Pre-Series A | I17: Early | J17: Healthtech | K17: Bengaluru | L17: IAN Alpha Fund; Silver Needle | M17: IAN Alpha Fund; IvyCap Ventures; Silver Needle | N17: entrackr | inc42 | et | O17: 3 | P17: 0 | R17: https://entrackr.com/snippets/neuroscience-startup-brainsight-ai-raises-5-mn-8602138
A18: R250108-hbits | B18: hBits | C18: 45665 | D18: 45658 | E18: 4.657 | F18: 40 | G18: Rs 40 crore | H18: Series A | I18: Early | J18: Fintech | K18: Mumbai | L18: Capricon Realty | M18: Capricon Realty | N18: entrackr | inc42 | O18: 2 | P18: 1.2 | R18: https://entrackr.com/snippets/proptech-startup-hbits-raises-rs-40-cr-in-series-a-8601862
A19: R250108-rasluxuryskinc | B19: RAS Luxury Skincare | C19: 45665 | D19: 45658 | E19: 5 | F19: 42.94 | G19: $5 million | H19: Series A | I19: Early | J19: Ecommerce | K19: Raipur | L19: Unilever Ventures | M19: Unilever Ventures; Amazon Smbhav Venture Fund; Sixth Sense Ventures | N19: entrackr | inc42 | et | O19: 3 | P19: 0 | R19: https://entrackr.com/snippets/ras-luxury-skincare-raises-5-mn-led-by-unilever-ventures-8600516
A20: R250109-beyondsnack | B20: Beyond Snack | C20: 45666 | D20: 45658 | E20: 8.3 | F20: 71.26 | G20: $8.3 million | H20: Series A | I20: Early | J20: Ecommerce | K20: Unknown | L20: 12 Flags Group | M20: 12 Flags Group; NAB Ventures; Enrission India Capital; FAAD Network | N20: entrackr | inc42 | et | vccircle | O20: 4 | P20: 0 | Q20: C07 | R20: https://entrackr.com/snippets/beyond-snack-raises-83-mn-in-series-a-round-8604226
A21: R250109-grayquest | B21: GrayQuest | C21: 45666 | D21: 45658 | E21: 9.319 | F21: 80 | G21: Rs 80 crore | H21: Series B | I21: Growth | J21: Fintech | K21: Mumbai | L21: IIFL Fintech Fund; Claypond Capital | M21: IIFL Fintech Fund; Claypond Capital; Pravega Ventures; Weizmann Group; Telama Family Office; Apurva Parekh from the Pidilite Family Office | N21: entrackr | inc42 | et | vccircle | O21: 4 | P21: 0.2 | R21: https://entrackr.com/news/grayquest-raises-93-mn-from-iifl-fintech-fund-claypond-and-pravega-8605812
A22: R250109-infinityfincor | B22: Infinity Fincorp | C22: 45666 | D22: 45658 | E22: 35 | F22: 300.48 | G22: $35 million | H22: Undisclosed | I22: Undisclosed | J22: Fintech | K22: Mumbai | L22: Jungle Ventures | M22: Jungle Ventures; Archerman Capital; Magnifico | N22: entrackr | inc42 | et | O22: 3 | P22: 133.3 | Q22: C04 C15 | R22: https://entrackr.com/snippets/infinity-fincorp-solutions-closes-35-mn-round-8603735
A23: R250109-innovaccer | B23: Innovaccer | C23: 45666 | D23: 45658 | E23: 275 | F23: 2360.88 | G23: $275 million | H23: Series F | I23: Late | J23: Healthtech | K23: Unknown | M23: B Capital Group; Banner Health; Danaher Ventures LLC; Generation Investment Management; Kaiser Permanente; M12 | N23: entrackr | inc42 | et | vccircle | O23: 4 | P23: 0 | Q23: C07 | R23: https://economictimes.indiatimes.com/tech/funding/saas-firm-innovaccer-closes-275-million-funding-to-build-more-on-ai-cloud/articleshow/117092526.cms
A24: R250109-integrishealth | B24: Integris Health | C24: 45666 | D24: 45658 | H24: Undisclosed | I24: Undisclosed | J24: Healthtech | K24: Unknown | M24: Mukul Agarwal; India SME Fund; Everstone Capital | N24: entrackr | O24: 1 | Q24: C03 C04 C07 | R24: https://entrackr.com/snippets/integris-health-raises-primary-capital-ahead-of-planned-ipo-8604374
A25: R250109-revivo | B25: Revivo | C25: 45666 | D25: 45658 | H25: Pre-Series A | I25: Early | J25: Consumer Services | K25: Unknown | L25: Inflection Point Ventures | M25: Inflection Point Ventures | N25: inc42 | O25: 1 | Q25: C03 C07 | R25: https://inc42.com/buzz/from-innovaccer-to-beyond-snack-indian-startups-raised-432-mn-this-week/
A26: R250109-waycool | B26: WayCool | C26: 45666 | D26: 45658 | E26: 4.4 | F26: 37.77 | G26: $4.4 Mn | H26: Undisclosed | I26: Undisclosed | J26: Agritech | K26: Chennai | L26: Trifecta Capital | M26: Trifecta Capital; Alteria Capital; Stride Ventures | N26: inc42 | O26: 1 | P26: 0 | Q26: C04 | R26: https://inc42.com/buzz/from-innovaccer-to-beyond-snack-indian-startups-raised-432-mn-this-week/
A27: R250110-quash | B27: Quash | C27: 45667 | D27: 45658 | E27: 0.635 | F27: 5.46 | G27: $635,000 | H27: Pre-Seed | I27: Early | J27: Enterprise Tech | K27: Bengaluru | L27: Arali Ventures | M27: Arali Ventures; Java Capital; PeerCheque; DeVC; Abhishek Goyal | N27: entrackr | inc42 | O27: 2 | P27: 0 | R27: https://entrackr.com/snippets/agentic-ai-startup-quash-raises-pre-seed-round-led-by-arali-ventures-8608038
A28: R250110-reputai | B28: RePut.ai | C28: 45667 | D28: 45658 | E28: 1 | F28: 8.6 | G28: $1 million | H28: Pre-Seed | I28: Early | J28: Enterprise Tech | K28: Bengaluru | L28: GrowthCap Venture | M28: GrowthCap Ventures; Vipul Parekh; Abhijeet Kumar; Vishal Jain; Anshul Sharan | N28: entrackr | inc42 | O28: 2 | P28: 0 | R28: https://inc42.com/buzz/from-innovaccer-to-beyond-snack-indian-startups-raised-432-mn-this-week/
A29: R250113-bobabhai | B29: Boba Bhai | C29: 45670 | D29: 45658 | E29: 3.46 | F29: 30 | G29: Rs 30 crore | H29: Series A | I29: Early | J29: Consumer Services | K29: Bengaluru | L29: 8i Ventures | M29: 8i Ventures; Titan Capital Winners Fund; Global Growth Capital; DevC; Z47 | N29: entrackr | inc42 | et | O29: 3 | P29: 1.8 | R29: https://entrackr.com/snippets/bubble-tea-brand-boba-bhai-raises-rs-30-cr-in-series-a-round-8614194
A30: R250113-weworkindia | B30: WeWork India | C30: 45670 | D30: 45658 | E30: 57.7 | F30: 500.26 | G30: $57.7 Mn | H30: Undisclosed | I30: Undisclosed | J30: Real Estate Tech | K30: Unknown | N30: inc42 | O30: 1 | P30: 0 | Q30: C04 C05 C07 | R30: https://inc42.com/buzz/from-netradyne-to-foxtale-indian-startups-raised-308-mn-this-week/
A31: R250114-bgauss | B31: BGauss | C31: 45671 | D31: 45658 | E31: 18.598 | F31: 161 | G31: Rs 161 crore | H31: Undisclosed | I31: Undisclosed | J31: Cleantech | K31: Pune | L31: Bharat Value Fund | M31: Bharat Value Fund | N31: entrackr | inc42 | et | O31: 3 | P31: 0 | Q31: C04 | R31: https://entrackr.com/news/ev-two-wheeler-manufacturer-bgauss-raises-rs-161-cr-8620040
A32: R250114-bharatpe | B32: BharatPe | C32: 45671 | D32: 45658 | E32: 17.3 | F32: 149.77 | G32: $17.3 Mn | H32: Debt | I32: Debt | J32: Fintech | K32: Unknown | M32: Neo Wealth; Trifecta Capital | N32: inc42 | O32: 1 | P32: 0 | Q32: C07 | R32: https://inc42.com/buzz/from-netradyne-to-foxtale-indian-startups-raised-308-mn-this-week/
A33: R250114-greenstitch | B33: GreenStitch | C33: 45671 | D33: 45658 | E33: 1.2 | F33: 10.39 | G33: $1.2 million | H33: Seed | I33: Early | J33: Ecommerce | K33: Bengaluru | L33: Equirus InnovateX Fund | M33: Equirus InnovateX Fund; Ivycap Ventures; Warmup Ventures; Zeca Ventures; Pankaj Vermani; Amit Kumar | N33: entrackr | et | O33: 2 | P33: 0 | R33: https://economictimes.indiatimes.com/tech/funding/climate-tech-startup-greenstitch-raises-1-2-million-from-equirus-innovatex-fund-others/articleshow/117237257.cms
A34: R250114-tractorfactory | B34: Tractor Factory | C34: 45671 | D34: 45658 | E34: 0.462 | F34: 4 | G34: Rs 4 crore | H34: Pre-Seed | I34: Early | J34: Ecommerce | K34: Jabalpur | L34: All In Capital | M34: All In Capital; Bharat Founders Fund; DevC; Dhingra Partners Prosperity Trust; Samir Sood; Abhishek Goyal; Aayush Phumbra; Puneet Kumar; Additionally; Steadview Capital | N34: entrackr | inc42 | et | O34: 3 | P34: 8.2 | R34: https://entrackr.com/snippets/tractor-factory-raises-500k-in-pre-seed-round-led-by-all-in-capital-8619966
A35: R250115-eccentricengin | B35: Eccentric | C35: 45672 | D35: 45658 | E35: 5 | F35: 43.21 | G35: $5 million | H35: Pre-Series A | I35: Early | J35: Enterprise Tech | K35: Unknown | L35: Exfinity Venture Partners; Arkam Ventures | M35: Exfinity Venture Partners; Arkam Ventures | N35: entrackr | inc42 | et | O35: 3 | P35: 0 | Q35: C07 | R35: https://entrackr.com/snippets/eccentric-engine-raises-5-mn-in-pre-series-a-round-8622777
A36: R250115-ecozen | B36: Ecozen | C36: 45672 | D36: 45658 | E36: 23 | F36: 198.77 | G36: $23 million | H36: Debt | I36: Debt | J36: Agritech | K36: Pune | M36: Northern Arc Capital Limited; Maanaveeya Development; Finance | N36: entrackr | inc42 | O36: 2 | P36: 0 | R36: https://entrackr.com/news/climate-tech-startup-ecozen-raises-23-mn-in-debt-8623678
A37: R250115-erlysign | B37: ErlySign | C37: 45672 | D37: 45658 | E37: 1.851 | F37: 16 | G37: Rs 16 crore | H37: Pre-Series A | I37: Early | J37: Healthtech | K37: Unknown | L37: Ashish Kacholia | M37: Ashish Kacholia | N37: entrackr | inc42 | O37: 2 | P37: 2.9 | Q37: C07 | R37: https://inc42.com/buzz/from-netradyne-to-foxtale-indian-startups-raised-308-mn-this-week/
A38: R250115-eulermotors | B38: Euler Motors | C38: 45672 | D38: 45658 | E38: 20 | F38: 172.84 | G38: $20 Mn | H38: Debt | I38: Debt | J38: Cleantech | K38: Delhi NCR | N38: inc42 | O38: 1 | P38: 0 | Q38: C05 | R38: https://inc42.com/buzz/from-netradyne-to-foxtale-indian-startups-raised-308-mn-this-week/
A39: R250115-foxtale | B39: Foxtale | C39: 45672 | D39: 45658 | E39: 30 | F39: 259.26 | G39: $30 million | H39: Series C | I39: Growth | J39: Ecommerce | K39: Mumbai | L39: KOSÉ Corporation | M39: KOSÉ Corporation; Panthera Growth Partners; Z47; Kae Capital | N39: entrackr | inc42 | et | O39: 3 | P39: 0 | R39: https://entrackr.com/news/d2c-skincare-brand-foxtale-raises-30-mn-8623443
A40: R250115-orbitaid | B40: OrbitAID | C40: 45672 | D40: 45658 | E40: 1.5 | F40: 12.96 | G40: $1.5 million | H40: Pre-Seed | I40: Early | J40: Deeptech | K40: Chennai | L40: Unicorn India Ventures | M40: Unicorn India Ventures; Tamil Nadu Startup; Innovation Mission; TANSIM | N40: entrackr | inc42 | et | O40: 3 | P40: 0 | R40: https://entrackr.com/snippets/spacetech-startup-orbitaid-raises-15-mn-led-by-unicorn-india-ventures-8622828
...

Sheet By Sector
A1: Rounds by sector
A2: PivotTable on the Rounds table. It refreshes when the file opens; drag fields to re-cut it.
B4: Values
A5: Sector | B5: Rounds | C5: Total USD mn | D5: Average USD mn
A6: Ecommerce | B6: 478 | C6: 4180.835 | D6: 9.5671281
A7: Fintech | B7: 238 | C7: 5687.77 | D7: 25.278978
A8: Artificial Intelligence | B8: 216 | C8: 3571.075 | D8: 18.035732
A9: Enterprise Tech | B9: 177 | C9: 2460.343 | D9: 15.002091
A10: Advanced Hardware & Technology | B10: 167 | C10: 1160.449 | D10: 7.4867677
A11: Cleantech | B11: 151 | C11: 2122.735 | D11: 14.639552
A12: Healthtech | B12: 137 | C12: 1640.126 | D12: 12.813484
A13: Consumer Services | B13: 125 | C13: 1274.084 | D13: 11.078991
A14: Media & Entertainment | B14: 64 | C14: 456.963 | D14: 8.4622778
A15: Deeptech | B15: 49 | C15: 206.335 | D15: 4.3901064
A16: Travel Tech | B16: 45 | C16: 590.648 | D16: 13.423818
A17: Agritech | B17: 45 | C17: 470.834 | D17: 10.949628
... A25: Grand Total | B25: 2178 | C25: 28468.859 | D25: 14.142503

Sheet By Stage
A1: Rounds by stage
A2: PivotTable on the Rounds table. It refreshes when the file opens; drag fields to re-cut it.
B4: Values
A5: Stage | B5: Rounds | C5: Total USD mn | D5: Average USD mn
A6: Pre-Seed | B6: 242 | C6: 203.326 | D6: 0.92842922
A7: Seed | B7: 467 | C7: 1702.189 | D7: 3.7826422
A8: Angel | B8: 9 | C8: 4.719 | D8: 0.7865
A9: Pre-Series A | B9: 231 | C9: 569.341 | D9: 2.5762036
A10: Series A | B10: 311 | C10: 3070.803 | D10: 9.9701396
A11: Pre-Series B | B11: 25 | C11: 205.636 | D11: 8.5681667
A12: Series B | B12: 150 | C12: 4126.042 | D12: 27.691557
A13: Pre-Series C | B13: 7 | C13: 77.178 | D13: 11.025429
A14: Series C | B14: 51 | C14: 2431.568 | D14: 48.63136
A15: Series D | B15: 22 | C15: 952.316 | D15: 43.287091
A16: Series E | B16: 11 | C16: 869.889 | D16: 79.080818
A17: Series F | B17: 12 | C17: 1464.217 | D17: 122.01808
... A24: Grand Total | B24: 2178 | C24: 28468.859 | D24: 14.142503

Sheet By City
A1: Rounds by city
A2: PivotTable on the Rounds table. It refreshes when the file opens; drag fields to re-cut it.
B4: Values
A5: City | B5: Rounds | C5: Total USD mn | D5: Average USD mn
A6: Bengaluru | B6: 461 | C6: 6699.193 | D6: 14.755932
A7: Delhi NCR | B7: 283 | C7: 2980.407 | D7: 10.997812
A8: Mumbai | B8: 191 | C8: 4648.204 | D8: 25.261978
A9: Pune | B9: 52 | C9: 347.969 | D9: 7.1014082
A10: Chennai | B10: 52 | C10: 403.913 | D10: 8.07826
A11: Hyderabad | B11: 51 | C11: 560.729 | D11: 10.994686
A12: Ahmedabad | B12: 18 | C12: 156.199 | D12: 9.7624375
A13: Jaipur | B13: 15 | C13: 98.34 | D13: 7.5646154
A14: Kolkata | B14: 8 | C14: 21.031 | D14: 2.628875
A15: Chandigarh | B15: 7 | C15: 25.884 | D15: 3.6977143
A16: Surat | B16: 6 | C16: 38.034 | D16: 7.6068
A17: Bhubaneswar | B17: 5 | C17: 8.333 | D17: 2.08325
... A39: Grand Total | B39: 2178 | C39: 28468.859 | D39: 14.142503

Sheet Checks
A1: The 18 automated checks
A2: Every round is tested on each run. A flag sends the round to a person; nothing is corrected automatically.
A4: ID | B4: Category | C4: Check | D4: Rule | E4: Severity | F4: Rounds checked | G4: Rounds flagged | H4: Share flagged
A5: C01 | B5: Nulls | C5: Company name missing | D5: company is blank | E5: error | F5: 2178 | G5: 0 | H5: 0 | I5: ●
A6: C02 | B6: Nulls | C6: Announcement date missing | D6: announced_date is blank or not a date | E6: error | F6: 2178 | G6: 0 | H6: 0 | I6: ●
A7: C03 | B7: Nulls | C7: Amount undisclosed | D7: no source reports an amount | E7: info | F7: 2178 | G7: 165 | H7: 0.0758 | I7: ●
A8: C04 | B8: Nulls | C8: Stage undisclosed | D8: no source names the round stage | E8: info | F8: 2178 | G8: 527 | H8: 0.242 | I8: ●
A9: C05 | B9: Nulls | C9: No investor named | D9: no source names an investor | E9: info | F9: 2178 | G9: 124 | H9: 0.0569 | I9: ●
A10: C06 | B10: Nulls | C10: Sector unclassified | D10: no sector label in a source table and no keyword match | E10: warning | F10: 2178 | G10: 136 | H10: 0.0624 | I10: ●
A11: C07 | B11: Nulls | C11: City unknown | D11: no report says where the company is based | E11: info | F11: 2178 | G11: 950 | H11: 0.4362 | I11: ●
A12: C08 | B12: Duplicates | C12: Duplicate report | D12: one article URL appears more than once in the source records | E12: error | F12: 2178 | G12: 0 | H12: 0 | I12: ●
A13: C09 | B13: Duplicates | C13: Possible duplicate round | D13: same company has another round within 45 days | E13: warning | F13: 2178 | G13: 29 | H13: 0.0133 | I13: ●
A14: C10 | B14: Validity | C14: Date outside tracking window | D14: announced_date before 2025-01-01 or in the future | E14: error | F14: 2178 | G14: 0 | H14: 0 | I14: ●
A15: C11 | B15: Outliers | C15: Amount outlier for its stage | D15: log10(amount) beyond 1.5 x IQR for the stage (stages with at least 10 amounts) | E15: warning | F15: 2178 | G15: 26 | H15: 0.0119 | I15: ●
A16: C12 | B16: Outliers | C16: Implausible amount | D16: amount below $0.01 Mn or above $2000 Mn | E16: warning | F16: 2178 | G16: 0 | H16: 0 | I16: ●
... A22: C18 | B22: Cross-source | C22: Stage disagreement | D22: two detailed sources state different stages | E22: warning | F22: 2178 | G22: 31 | H22: 0.0142 | I22: ●

Sheet Exceptions
A1: Exceptions: every flag raised by the checks
A2: Filter by Check ID or Severity. The Flags column on the Rounds sheet lists the same IDs per round.
A4: Check ID | B4: Check | C4: Severity | D4: Round ID | E4: Company | F4: Announced | G4: Detail
A5: C03 | B5: Amount undisclosed | C5: info | D5: R250102-klassroom | E5: Klassroom | F5: 45659 | G5: amount not disclosed by any source
A6: C03 | B6: Amount undisclosed | C6: info | D6: R250106-blackcarrot | E6: BlackCarrot | F6: 45663 | G6: amount not disclosed by any source
A7: C03 | B7: Amount undisclosed | C7: info | D7: R250107-bodmastechnolo | E7: Bodmas Technologies | F7: 45664 | G7: amount not disclosed by any source
A8: C03 | B8: Amount undisclosed | C8: info | D8: R250109-integrishealth | E8: Integris Health | F8: 45666 | G8: amount not disclosed by any source
A9: C03 | B9: Amount undisclosed | C9: info | D9: R250109-revivo | E9: Revivo | F9: 45666 | G9: amount not disclosed by any source
A10: C03 | B10: Amount undisclosed | C10: info | D10: R250116-motorfloor | E10: Motorfloor | F10: 45673 | G10: amount not disclosed by any source
A11: C03 | B11: Amount undisclosed | C11: info | D11: R250122-spare8 | E11: Spare8 | F11: 45679 | G11: amount not disclosed by any source
A12: C03 | B12: Amount undisclosed | C12: info | D12: R250127-tracknow | E12: trackNOW | F12: 45684 | G12: amount not disclosed by any source
A13: C03 | B13: Amount undisclosed | C13: info | D13: R250129-manastuspace | E13: Manastu Space | F13: 45686 | G13: amount not disclosed by any source
A14: C03 | B14: Amount undisclosed | C14: info | D14: R250203-builditindia | E14: BuilditIndia | F14: 45691 | G14: amount not disclosed by any source
A15: C03 | B15: Amount undisclosed | C15: info | D15: R250203-curefoods | E15: Curefoods | F15: 45691 | G15: amount not disclosed by any source
A16: C03 | B16: Amount undisclosed | C16: info | D16: R250204-coluxe | E16: COLUXE | F16: 45692 | G16: amount not disclosed by any source
... A2137: C18 | B2137: Stage disagreement | C2137: warning | D2137: R260818-rezolv | E2137: Rezolv | F2137: 46252 | G2137: entrackr: Series A; et: Debt; inc42: Series A

Sheet Source rules
A1: Source of truth, field by field
A2: When sources disagree, these rules decide what goes on the Rounds sheet. The disagreement is still flagged.
A4: Field | B4: Source-of-truth rule | C4: Why
A5: Company | B5: The spelling most reports agree on, compared without case or punctuation. Ties go to the Inc42 deal table, then Entrackr, then ET. | C5: Typos differ by source; the spelling several sources share is the safest.
A6: Announced | B6: The earliest publication date among the reports of the round. | C6: Later reports are follow-ups. The first report is closest to the announcement.
A7: Amount (as reported) | B7: The first source that states an amount, in this order: Entrackr, Inc42, ET, VCCircle. Every other figure is kept and compared, never averaged. | C7: Entrackr quotes the announcement currency and usually the dollar equivalent beside it. Inc42 converts everything to dollars. ET often reports a round before its final size is known. VCCircle is a headline only.
A8: Amount (USD mn) | B8: Dollars as stated when the chosen source reports in dollars. Rupee figures are converted at the ECB reference rate for the announcement date. | C8: One published rate per day makes every conversion reproducible.
A9: Amount (INR cr) | B9: Rupees as stated when the chosen source reports in rupees, otherwise converted at the same rate. | C9: Kept beside the dollar figure so either can be checked against the source.
A10: Stage | B10: The first source that names a stage: Inc42 table, Entrackr, ET, VCCircle. | C10: The Inc42 table has a dedicated round-type column. The others are read from prose.
A11: Lead investors / Investors | B11: Every investor named by Inc42, Entrackr or ET, each listed once. | C11: Sources name different subsets of a syndicate, so the union is the fullest list.
A12: Sector | B12: The Inc42 table's sector, with spelling variants merged. If Inc42 did not list the round: the sector Inc42 gave the same company in another round, else a keyword rule on the article's description of the company. Otherwise Unclassified. | C12: One taxonomy for all rounds. The basis is recorded per round in rounds.csv.
A13: City | B13: The city an Entrackr or ET article says the company is based in. If no report of this round says so, the city from another round of the same company. Otherwise Unknown. | C13: Only stated locations are used. Nothing is filled in from memory.
A14: Sources | B14: Every source with a matched report. A VCCircle headline can confirm a round but never creates one. | C14: A company name read from a URL is too rough to establish a round on its own.

Sheet Reports
A1: Source reports matched to a round
A2: One row per article, table row or headline. Amounts are exactly as each source gave them.
A4: Record ID | B4: Round ID | C4: Source | D4: Published | E4: Company in report | F4: Amount as reported | G4: INR cr | H4: USD mn | I4: Stage | J4: Lead investors | K4: Link
A5: INC-20250104-01 | B5: R250102-ayefinance | C5: Inc42 | D5: 45659 | E5: Aye Finance | F5: $12.8 Mn | H5: 12.8 | I5: Debt | K5: https://inc42.com/buzz/from-aye-finance-to-klassroom-indian-startups-raised-14-mn-this-week/
A6: ENT-8584928 | B6: R250102-cargofl | C6: Entrackr | D6: 45659 | E6: CargoFL | F6: Rs 6.75 crore | G6: 6.75 | I6: Seed | J6: YourNest Venture Capital | K6: https://entrackr.com/snippets/cargofl-raises-seed-funding-round-8584928
A7: INC-20250104-02 | B7: R250102-cargofl | C7: Inc42 | D7: 45659 | E7: CargoFL | F7: $787K | H7: 0.787 | I7: Seed | J7: YourNest Venture Capital | K7: https://inc42.com/buzz/from-aye-finance-to-klassroom-indian-startups-raised-14-mn-this-week/
A8: INC-20250104-04 | B8: R250102-klassroom | C8: Inc42 | D8: 45659 | E8: Klassroom | I8: Pre-Series A | K8: https://inc42.com/buzz/from-aye-finance-to-klassroom-indian-startups-raised-14-mn-this-week/
A9: ENT-8591029 | B9: R250104-oyo | C9: Entrackr | D9: 45661 | E9: Oyo | F9: Rs 550 crore | G9: 550 | H9: 65 | I9: Undisclosed | K9: https://entrackr.com/news/oyo-raises-65-mn-from-ritesh-agarwals-redsprig-innovation-8591029
A10: INC-20250111-02 | B10: R250104-oyo | C10: Inc42 | D10: 45662 | E10: OYO | F10: $65 Mn | H10: 65 | I10: Undisclosed | J10: Redsprig Innovation Partners | K10: https://inc42.com/buzz/from-innovaccer-to-beyond-snack-indian-startups-raised-432-mn-this-week/
A11: INC-20250111-18 | B11: R250106-blackcarrot | C11: Inc42 | D11: 45663 | E11: BlackCarrot | I11: Seed | J11: Circle | K11: https://inc42.com/buzz/from-innovaccer-to-beyond-snack-indian-startups-raised-432-mn-this-week/
A12: ENT-8594981 | B12: R250106-consintai | C12: Entrackr | D12: 45663 | E12: Consint.AI | F12: Rs 5 crore | G12: 5 | I12: Seed | J12: Equanimity Ventures; Seafund | K12: https://entrackr.com/snippets/genai-startup-consintai-raises-rs-5-cr-in-seed-round-8594981
A13: ET-117009532 | B13: R250106-consintai | C13: The Economic Times | D13: 45664 | E13: Consint AI | F13: Rs 5 crore | G13: 5 | I13: Undisclosed | K13: https://economictimes.indiatimes.com/tech/funding/healthtech-startup-consint-ai-raises-rs-5-crore/articleshow/117009532.cms
A14: ENT-8594970 | B14: R250106-spintly | C14: Entrackr | D14: 45663 | E14: Spintly | F14: Rs 3.5 crore | G14: 3.5 | I14: Seed | J14: Spyre VC; Chakra Growth Fund; Alumni Ventures; Doctor Technology | K14: https://entrackr.com/snippets/proptech-startup-spintly-raises-rs-35-cr-in-extended-seed-round-8594970
A15: INC-20250111-17 | B15: R250106-spintly | C15: Inc42 | D15: 45663 | E15: Spintly | F15: $407K | H15: 0.407 | I15: Seed | K15: https://inc42.com/buzz/from-innovaccer-to-beyond-snack-indian-startups-raised-432-mn-this-week/
A16: INC-20250111-19 | B16: R250107-bodmastechnolo | C16: Inc42 | D16: 45664 | E16: Bodmas Technologies | I16: Undisclosed | K16: https://inc42.com/buzz/from-innovaccer-to-beyond-snack-indian-startups-raised-432-mn-this-week/
A17: ENT-8598190 | B17: R250107-emoenergy | C17: Entrackr | D17: 45664 | E17: EMO Energy | F17: $6.2 million | H17: 6.2 | I17: Series A | J17: Subhkam Ventures; Transition VC | K17: https://entrackr.com/snippets/emo-energy-raises-62-mn-in-series-a-round-8598190
A18: ET-117002145 | B18: R250107-emoenergy | C18: The Economic Times | D18: 45664 | E18: Emo Energy | F18: $6.2 million | H18: 6.2 | I18: Undisclosed | J18: Subhkam Ventures | K18: https://economictimes.indiatimes.com/tech/funding/subhkam-ventures-leads-6-2-million-round-in-emo-energy/articleshow/117002145.cms
A19: INC-20250111-06 | B19: R250107-emoenergy | C19: Inc42 | D19: 45664 | E19: EMO Energy | F19: $6.2 Mn | H19: 6.2 | I19: Series A | J19: Subhkam Ventures | K19: https://inc42.com/buzz/from-innovaccer-to-beyond-snack-indian-startups-raised-432-mn-this-week/
A20: ENT-8598246 | B20: R250107-kibisports | C20: Entrackr | D20: 45664 | E20: KIBI Sports | F20: $100,000 | H20: 0.1 | I20: Pre-Seed | K20: https://entrackr.com/snippets/kibi-sports-raises-100k-in-pre-seed-funding-8598246
A21: ENT-8597800 | B21: R250107-moonrider | C21: Entrackr | D21: 45664 | E21: Moonrider | F21: $2.2 million | G21: 19 | H21: 2.2 | I21: Seed | J21: Micelio Technology Fund | K21: https://entrackr.com/snippets/electric-tractor-startup-moonrider-raises-22-mn-in-seed-round-8597800
A22: ET-117028244 | B22: R250107-moonrider | C22: The Economic Times | D22: 45664 | E22: Moonrider | F22: $2.2 million | G22: 19 | H22: 2.2 | I22: Undisclosed | J22: Micelio Technology Fund | K22: https://economictimes.indiatimes.com/tech/funding/electric-tractor-technology-startup-moonrider-raises-2-2-million/articleshow/117028244.cms
A23: INC-20250111-13 | B23: R250107-moonrider | C23: Inc42 | D23: 45665 | E23: Moonrider | F23: $2.2 Mn | H23: 2.2 | I23: Seed | J23: Micelio Fund | K23: https://inc42.com/buzz/from-innovaccer-to-beyond-snack-indian-startups-raised-432-mn-this-week/
A24: ENT-8598547 | B24: R250107-obenelectric | C24: Entrackr | D24: 45664 | E24: Oben Electric | F24: Rs 50 crore | G24: 50 | H24: 6 | I24: Series A | K24: https://entrackr.com/snippets/oben-electric-raises-6-mn-in-series-a-8598547
A25: INC-20250111-07 | B25: R250107-obenelectric | C25: Inc42 | D25: 45664 | E25: Oben Electric | F25: $5.8 Mn | H25: 5.8 | I25: Series A | K25: https://inc42.com/buzz/from-innovaccer-to-beyond-snack-indian-startups-raised-432-mn-this-week/
A26: INC-20250111-14 | B26: R250107-pratilipi | C26: Inc42 | D26: 45664 | E26: Pratilipi | F26: $1.2 Mn | H26: 1.2 | I26: Undisclosed | J26: Alteria Capital | K26: https://inc42.com/buzz/from-innovaccer-to-beyond-snack-indian-startups-raised-432-mn-this-week/
A27: ET-117013023 | B27: R250107-vehanttechnolo | C27: The Economic Times | D27: 45664 | E27: Vehant Technologies | F27: $9 million | G27: 77 | H27: 9 | I27: Debt | K27: https://economictimes.indiatimes.com/tech/funding/vehant-technologies-raises-9-million-from-true-north-through-ncds-plans-ipo-by-2026/articleshow/117013023.cms
A28: ENT-8601401 | B28: R250107-vehanttechnolo | C28: Entrackr | D28: 45665 | E28: Vehant Technologies | F28: $9 million | G28: 75 | H28: 9 | I28: Undisclosed | K28: https://entrackr.com/snippets/vehant-technologies-raises-9-mn-from-true-north-8601401
A29: ENT-8598758 | B29: R250107-zoplar | C29: Entrackr | D29: 45664 | E29: Zoplar | F29: $3.4 million | H29: 3.4 | I29: Series A | J29: Blume Ventures | K29: https://entrackr.com/snippets/blume-ventures-leads-34-mn-round-in-zoplar-8598758
A30: INC-20250111-12 | B30: R250107-zoplar | C30: Inc42 | D30: 45664 | E30: Zoplar | F30: $3.4 Mn | H30: 3.4 | I30: Series A | J30: Blume Ventures | K30: https://inc42.com/buzz/from-innovaccer-to-beyond-snack-indian-startups-raised-432-mn-this-week/
A31: ENT-8602138 | B31: R250108-brainsightai | C31: Entrackr | D31: 45665 | E31: BrainSight AI | F31: $5 million | H31: 5 | I31: Pre-Series A | J31: IAN Alpha Fund; Silver Needle | K31: https://entrackr.com/snippets/neuroscience-startup-brainsight-ai-raises-5-mn-8602138
A32: ET-117059845 | B32: R250108-brainsightai | C32: The Economic Times | D32: 45665 | E32: BrainSightAI | F32: $5 million | H32: 5 | I32: Pre-Series A | J32: IAN Alpha Fund | K32: https://economictimes.indiatimes.com/tech/funding/neuroscience-startup-brainsightai-raises-5-million-from-ian-alpha-fund-others/articleshow/117059845.cms
A33: INC-20250111-09 | B33: R250108-brainsightai | C33: Inc42 | D33: 45665 | E33: BrainSinghtAI | F33: $5 Mn | H33: 5 | I33: Pre-Series A | J33: IAN Alpha Fund | K33: https://inc42.com/buzz/from-innovaccer-to-beyond-snack-indian-startups-raised-432-mn-this-week/
A34: ENT-8601862 | B34: R250108-hbits | C34: Entrackr | D34: 45665 | E34: hBits | F34: Rs 40 crore | G34: 40 | I34: Series A | K34: https://entrackr.com/snippets/proptech-startup-hbits-raises-rs-40-cr-in-series-a-8601862
A35: INC-20250111-10 | B35: R250108-hbits | C35: Inc42 | D35: 45665 | E35: hBits | F35: $4.6 Mn | H35: 4.6 | I35: Series A | J35: Capricon Realty | K35: https://inc42.com/buzz/from-innovaccer-to-beyond-snack-indian-startups-raised-432-mn-this-week/
A36: ENT-8600516 | B36: R250108-rasluxuryskinc | C36: Entrackr | D36: 45665 | E36: RAS Luxury Skincare | F36: $5 million | H36: 5 | I36: Series A | J36: Unilever Ventures | K36: https://entrackr.com/snippets/ras-luxury-skincare-raises-5-mn-led-by-unilever-ventures-8600516
A37: ET-117033168 | B37: R250108-rasluxuryskinc | C37: The Economic Times | D37: 45665 | E37: RAS Luxury Skincare | F37: $5 million | H37: 5 | I37: Undisclosed | J37: Unilever Ventures; Unilever | K37: https://economictimes.indiatimes.com/tech/funding/beauty-brand-ras-luxury-skincare-raises-5-million-from-unilever-ventures-others/articleshow/117033168.cms
A38: INC-20250111-08 | B38: R250108-rasluxuryskinc | C38: Inc42 | D38: 45665 | E38: RAS Luxury | F38: $5 Mn | H38: 5 | I38: Series A | J38: Unilever Ventures | K38: https://inc42.com/buzz/from-innovaccer-to-beyond-snack-indian-startups-raised-432-mn-this-week/
A39: ENT-8604226 | B39: R250109-beyondsnack | C39: Entrackr | D39: 45666 | E39: Beyond Snack | F39: $8.3 million | H39: 8.3 | I39: Series A | J39: 12 Flags Group | K39: https://entrackr.com/snippets/beyond-snack-raises-83-mn-in-series-a-round-8604226
A40: ET-117059037 | B40: R250109-beyondsnack | C40: The Economic Times | D40: 45666 | E40: Beyond Snack | F40: $8.3 million | H40: 8.3 | I40: Undisclosed | J40: 12 Flags Group | K40: https://economictimes.indiatimes.com/tech/funding/banana-chips-brand-beyond-snack-bags-8-3-million-in-round-led-by-12-flags-group/articleshow/117059037.cms
A41: INC-20250111-05 | B41: R250109-beyondsnack | C41: Inc42 | D41: 45666 | E41: Beyond Snack | F41: $8.3 Mn | H41: 8.3 | I41: Series A | J41: 12 Flags Group | K41: https://inc42.com/buzz/from-innovaccer-to-beyond-snack-indian-startups-raised-432-mn-this-week/
...

Sheet Coverage
A1: Coverage check against Entrackr's weekly report
A2: A control total: the number of funded startups Entrackr counted each week, beside the rounds tracked here.
A4: Week start | B4: Week end | C4: Entrackr: funded startups | D4: Tracker: rounds | E4: Difference | F4: Entrackr: USD mn | G4: Tracker: USD mn
A5: 45656 | B5: 45661 | C5: 8 | D5: 4 | E5: -4 | F5: 33.44 | G5: 77.71
A6: 45663 | B6: 45668 | C6: 27 | D6: 23 | E6: -4 | F6: 466.45 | G6: 377.24
A7: 45670 | B7: 45675 | C7: 37 | D7: 32 | E7: -5 | F7: 780 | G7: 359.65
A8: 45677 | B8: 45682 | C8: 30 | D8: 29 | E8: -1 | F8: 248.87 | G8: 296.95
A9: 45684 | B9: 45689 | C9: 30 | D9: 28 | E9: -2 | F9: 240.85 | G9: 788.11
A10: 45712 | B10: 45717 | C10: 21 | D10: 21 | E10: 0 | F10: 105.87 | G10: 106.65
A11: 45719 | B11: 45724 | C11: 30 | D11: 33 | E11: 3 | F11: 355.02 | G11: 387.66
A12: 45726 | B12: 45731 | C12: 19 | D12: 16 | E12: -3 | F12: 462.27 | G12: 463.11
A13: 45733 | B13: 45738 | C13: 25 | D13: 27 | E13: 2 | F13: 176.44 | G13: 197.5
A14: 45740 | B14: 45745 | C14: 23 | D14: 27 | E14: 4 | F14: 152.49 | G14: 218.21
A15: 45747 | B15: 45752 | C15: 30 | D15: 30 | E15: 0 | F15: 357.29 | G15: 382.86
A16: 45754 | B16: 45759 | C16: 24 | D16: 23 | E16: -1 | F16: 181.21 | G16: 490.81
... A91: 46300 | B91: 46305 | C91: 28 | D91: 29 | E91: 1 | F91: 113.35 | G91: 154.89

Sheet Chart data
A1: Month | B1: Month start | C1: Rounds | D1: Funding USD mn | F1: Stage | G1: Rounds | I1: Sector | J1: Rounds | L1: City | M1: Rounds | O1: These tables feed the Dashboard charts. They are formulas on the Rounds sheet, so they follow any edit.
A2: Jan 25 | B2: 45658 | C2: =COUNTIF(Rounds!$D$2:$D$2179,B2) -> 116 | D2: =SUMIF(Rounds!$D$2:$D$2179,B2,Rounds!$E$2:$E$2179) -> 1899.66 | F2: Pre-Seed | G2: =COUNTIF(Rounds!$H$2:$H$2179,F2) -> 242 | I2: Ecommerce | J2: =COUNTIF(Rounds!$J$2:$J$2179,I2) -> 478 | L2: Bengaluru | M2: =COUNTIF(Rounds!$K$2:$K$2179,L2) -> 461
A3: Feb 25 | B3: 45689 | C3: =COUNTIF(Rounds!$D$2:$D$2179,B3) -> 93 | D3: =SUMIF(Rounds!$D$2:$D$2179,B3,Rounds!$E$2:$E$2179) -> 762.251 | F3: Seed | G3: =COUNTIF(Rounds!$H$2:$H$2179,F3) -> 467 | I3: Fintech | J3: =COUNTIF(Rounds!$J$2:$J$2179,I3) -> 238 | L3: Delhi NCR | M3: =COUNTIF(Rounds!$K$2:$K$2179,L3) -> 283
A4: Mar 25 | B4: 45717 | C4: =COUNTIF(Rounds!$D$2:$D$2179,B4) -> 105 | D4: =SUMIF(Rounds!$D$2:$D$2179,B4,Rounds!$E$2:$E$2179) -> 1451.488 | F4: Angel | G4: =COUNTIF(Rounds!$H$2:$H$2179,F4) -> 9 | I4: Artificial Intelligence | J4: =COUNTIF(Rounds!$J$2:$J$2179,I4) -> 216 | L4: Mumbai | M4: =COUNTIF(Rounds!$K$2:$K$2179,L4) -> 191
A5: Apr 25 | B5: 45748 | C5: =COUNTIF(Rounds!$D$2:$D$2179,B5) -> 120 | D5: =SUMIF(Rounds!$D$2:$D$2179,B5,Rounds!$E$2:$E$2179) -> 1037.828 | F5: Pre-Series A | G5: =COUNTIF(Rounds!$H$2:$H$2179,F5) -> 231 | I5: Enterprise Tech | J5: =COUNTIF(Rounds!$J$2:$J$2179,I5) -> 177 | L5: Pune | M5: =COUNTIF(Rounds!$K$2:$K$2179,L5) -> 52
A6: May 25 | B6: 45778 | C6: =COUNTIF(Rounds!$D$2:$D$2179,B6) -> 103 | D6: =SUMIF(Rounds!$D$2:$D$2179,B6,Rounds!$E$2:$E$2179) -> 1407.817 | F6: Series A | G6: =COUNTIF(Rounds!$H$2:$H$2179,F6) -> 311 | I6: Advanced Hardware & Technology | J6: =COUNTIF(Rounds!$J$2:$J$2179,I6) -> 167 | L6: Chennai | M6: =COUNTIF(Rounds!$K$2:$K$2179,L6) -> 52
A7: Jun 25 | B7: 45809 | C7: =COUNTIF(Rounds!$D$2:$D$2179,B7) -> 95 | D7: =SUMIF(Rounds!$D$2:$D$2179,B7,Rounds!$E$2:$E$2179) -> 1781.969 | F7: Pre-Series B | G7: =COUNTIF(Rounds!$H$2:$H$2179,F7) -> 25 | I7: Cleantech | J7: =COUNTIF(Rounds!$J$2:$J$2179,I7) -> 151 | L7: Hyderabad | M7: =COUNTIF(Rounds!$K$2:$K$2179,L7) -> 51
A8: Jul 25 | B8: 45839 | C8: =COUNTIF(Rounds!$D$2:$D$2179,B8) -> 108 | D8: =SUMIF(Rounds!$D$2:$D$2179,B8,Rounds!$E$2:$E$2179) -> 853.865 | F8: Series B | G8: =COUNTIF(Rounds!$H$2:$H$2179,F8) -> 150 | I8: Healthtech | J8: =COUNTIF(Rounds!$J$2:$J$2179,I8) -> 137 | L8: Ahmedabad | M8: =COUNTIF(Rounds!$K$2:$K$2179,L8) -> 18
A9: Aug 25 | B9: 45870 | C9: =COUNTIF(Rounds!$D$2:$D$2179,B9) -> 90 | D9: =SUMIF(Rounds!$D$2:$D$2179,B9,Rounds!$E$2:$E$2179) -> 890.882 | F9: Pre-Series C | G9: =COUNTIF(Rounds!$H$2:$H$2179,F9) -> 7 | I9: Consumer Services | J9: =COUNTIF(Rounds!$J$2:$J$2179,I9) -> 125 | L9: Jaipur | M9: =COUNTIF(Rounds!$K$2:$K$2179,L9) -> 15
A10: Sep 25 | B10: 45901 | C10: =COUNTIF(Rounds!$D$2:$D$2179,B10) -> 122 | D10: =SUMIF(Rounds!$D$2:$D$2179,B10,Rounds!$E$2:$E$2179) -> 1748.519 | F10: Series C | G10: =COUNTIF(Rounds!$H$2:$H$2179,F10) -> 51 | I10: Media & Entertainment | J10: =COUNTIF(Rounds!$J$2:$J$2179,I10) -> 64 | L10: Kolkata | M10: =COUNTIF(Rounds!$K$2:$K$2179,L10) -> 8
A11: Oct 25 | B11: 45931 | C11: =COUNTIF(Rounds!$D$2:$D$2179,B11) -> 105 | D11: =SUMIF(Rounds!$D$2:$D$2179,B11,Rounds!$E$2:$E$2179) -> 1972.44 | F11: Series D | G11: =COUNTIF(Rounds!$H$2:$H$2179,F11) -> 22 | I11: Deeptech | J11: =COUNTIF(Rounds!$J$2:$J$2179,I11) -> 49 | L11: Chandigarh | M11: =COUNTIF(Rounds!$K$2:$K$2179,L11) -> 7
A12: Nov 25 | B12: 45962 | C12: =COUNTIF(Rounds!$D$2:$D$2179,B12) -> 108 | D12: =SUMIF(Rounds!$D$2:$D$2179,B12,Rounds!$E$2:$E$2179) -> 1167.408 | F12: Series E | G12: =COUNTIF(Rounds!$H$2:$H$2179,F12) -> 11 | I12: Travel Tech | J12: =COUNTIF(Rounds!$J$2:$J$2179,I12) -> 45 | L12: Surat | M12: =COUNTIF(Rounds!$K$2:$K$2179,L12) -> 6
A13: Dec 25 | B13: 45992 | C13: =COUNTIF(Rounds!$D$2:$D$2179,B13) -> 86 | D13: =SUMIF(Rounds!$D$2:$D$2179,B13,Rounds!$E$2:$E$2179) -> 1199.164 | F13: Series F | G13: =COUNTIF(Rounds!$H$2:$H$2179,F13) -> 12 | I13: Agritech | J13: =COUNTIF(Rounds!$J$2:$J$2179,I13) -> 45 | L13: Bhubaneswar | M13: =COUNTIF(Rounds!$K$2:$K$2179,L13) -> 5
A14: Jan 26 | B14: 46023 | C14: =COUNTIF(Rounds!$D$2:$D$2179,B14) -> 115 | D14: =SUMIF(Rounds!$D$2:$D$2179,B14,Rounds!$E$2:$E$2179) -> 951.949 | F14: Series G | G14: =COUNTIF(Rounds!$H$2:$H$2179,F14) -> 6 | I14: Real Estate Tech | J14: =COUNTIF(Rounds!$J$2:$J$2179,I14) -> 45
A15: Feb 26 | B15: 46054 | C15: =COUNTIF(Rounds!$D$2:$D$2179,B15) -> 113 | D15: =SUMIF(Rounds!$D$2:$D$2179,B15,Rounds!$E$2:$E$2179) -> 2194.385 | F15: Series H+ | G15: =COUNTIF(Rounds!$H$2:$H$2179,F15) -> 1 | I15: Edtech | J15: =COUNTIF(Rounds!$J$2:$J$2179,I15) -> 39
A16: Mar 26 | B16: 46082 | C16: =COUNTIF(Rounds!$D$2:$D$2179,B16) -> 103 | D16: =SUMIF(Rounds!$D$2:$D$2179,B16,Rounds!$E$2:$E$2179) -> 1196.683 | F16: Bridge | G16: =COUNTIF(Rounds!$H$2:$H$2179,F16) -> 18
A17: Apr 26 | B17: 46113 | C17: =COUNTIF(Rounds!$D$2:$D$2179,B17) -> 97 | D17: =SUMIF(Rounds!$D$2:$D$2179,B17,Rounds!$E$2:$E$2179) -> 1066.09 | F17: Pre-IPO | G17: =COUNTIF(Rounds!$H$2:$H$2179,F17) -> 9
A18: May 26 | B18: 46143 | C18: =COUNTIF(Rounds!$D$2:$D$2179,B18) -> 73 | D18: =SUMIF(Rounds!$D$2:$D$2179,B18,Rounds!$E$2:$E$2179) -> 707.049 | F18: Debt | G18: =COUNTIF(Rounds!$H$2:$H$2179,F18) -> 79
A19: Jun 26 | B19: 46174 | C19: =COUNTIF(Rounds!$D$2:$D$2179,B19) -> 100 | D19: =SUMIF(Rounds!$D$2:$D$2179,B19,Rounds!$E$2:$E$2179) -> 2153.971 | F19: Undisclosed | G19: =COUNTIF(Rounds!$H$2:$H$2179,F19) -> 527
A20: Jul 26 | B20: 46204 | C20: =COUNTIF(Rounds!$D$2:$D$2179,B20) -> 95 | D20: =SUMIF(Rounds!$D$2:$D$2179,B20,Rounds!$E$2:$E$2179) -> 1043.929
A21: Aug 26 | B21: 46235 | C21: =COUNTIF(Rounds!$D$2:$D$2179,B21) -> 92 | D21: =SUMIF(Rounds!$D$2:$D$2179,B21,Rounds!$E$2:$E$2179) -> 1360.241
A22: Sep 26 | B22: 46266 | C22: =COUNTIF(Rounds!$D$2:$D$2179,B22) -> 105 | D22: =SUMIF(Rounds!$D$2:$D$2179,B22,Rounds!$E$2:$E$2179) -> 1453.458
A23: Oct 26 | B23: 46296 | C23: =COUNTIF(Rounds!$D$2:$D$2179,B23) -> 34 | D23: =SUMIF(Rounds!$D$2:$D$2179,B23,Rounds!$E$2:$E$2179) -> 167.813

Sheet About
A1: About this workbook
A3: What it is | B3: Every Indian startup funding round the tracker found since 01 January 2025, one row per round, with the reports that support it.
A4: Sources | B4: Entrackr and The Economic Times (articles), Inc42 (weekly deal tables), VCCircle (headlines). Only facts and links are stored, never article text.
A5: Reports read | B5: Entrackr 1,752; Inc42 1,771; The Economic Times 761; VCCircle 175 matched to a round.
A6: Exchange rate | B6: Rupee amounts are converted at the ECB reference rate for the announcement date (latest: 96.73 INR per USD on 11 Oct 2026).
A7: PivotTables | B7: By Sector, By Stage and By City are PivotTables on the Rounds table. They refresh when the file opens. After editing data: PivotTable Analyze > Refresh.
A8: Checks | B8: 18 automated checks run on every build. Results are on the Checks and Exceptions sheets.
A9: Rules | B9: The Source rules sheet says which source wins for each field, and why.
A10: Rebuild | B10: python -m funding_tracker update (see README.md in the repository)
A11: Repository | B11: https://github.com/pkjx29/funding-tracker
